export const sleep = (ms: number): Promise<void> =>
  new Promise((resolve) => setTimeout(resolve, ms));

export const retryWithBackoff = async <T>(
  fn: () => Promise<T>,
  maxRetries: number = 3,
  baseDelay: number = 1000
): Promise<T> => {
  let lastError: Error;

  for (let attempt = 0; attempt <= maxRetries; attempt++) {
    try {
      return await fn();
    } catch (error) {
      lastError = error as Error;

      if (attempt === maxRetries) {
        throw lastError;
      }

      const delay = baseDelay * Math.pow(2, attempt);
      console.warn(
        `Attempt ${attempt + 1} failed, retrying in ${delay}ms:`,
        error
      );
      await sleep(delay);
    }
  }

  throw lastError!;
};

export const getErrorMessage = (error: unknown): string => {
  if (error instanceof Error) {
    return error.message;
  }

  if (typeof error === "string") {
    return error;
  }

  return "An unexpected error occurred";
};
